ERROR 2024-11-26 04:50:54,032 log Internal Server Error: /disposal/
Traceback (most recent call last):
  File "/home/pi/rasp/rfid/views_v2.py", line 40, in disposal
    uid = rfid_reader.tagging()
          ^^^^^^^^^^^^^^^^^^^^^
  File "/home/pi/rasp/rfid/rfid_reader.py", line 44, in tagging
    raise CustomException("태깅 시간 초과", status_code=404)
rfid.exceptions.CustomException: 태깅 시간 초과

During handling of the above exception, another exception occurred:

Traceback (most recent call last):
  File "/usr/local/lib/python3.11/dist-packages/django/core/handlers/exception.py", line 55, in inner
    response = get_response(request)
               ^^^^^^^^^^^^^^^^^^^^^
  File "/usr/local/lib/python3.11/dist-packages/django/core/handlers/base.py", line 197, in _get_response
    response = wrapped_callback(request, *callback_args, **callback_kwargs)
               ^^^^^^^^^^^^^^^^^^^^^^^^^^^^^^^^^^^^^^^^^^^^^^^^^^^^^^^^^^^^
  File "/home/pi/rasp/rfid/views_v2.py", line 54, in disposal
    raise CustomException("태깅 중 오류 발생", status_code=500)
rfid.exceptions.CustomException: 태깅 중 오류 발생
ERROR 2024-11-26 04:50:54,035 basehttp "POST /disposal/ HTTP/1.1" 500 1860
ERROR 2024-11-26 04:50:54,060 log Internal Server Error: /favicon.ico
ERROR 2024-11-26 04:50:54,061 basehttp "GET /favicon.ico HTTP/1.1" 500 1860
ERROR 2024-11-26 04:51:13,942 log Internal Server Error: /favicon.ico
ERROR 2024-11-26 04:51:13,943 basehttp "GET /favicon.ico HTTP/1.1" 500 1860
ERROR 2024-11-26 05:05:34,557 log Internal Server Error: /disposal/
Traceback (most recent call last):
  File "/home/pi/rasp/rfid/views_v2.py", line 40, in disposal
    uid = rfid_reader.tagging()
          ^^^^^^^^^^^^^^^^^^^^^
  File "/home/pi/rasp/rfid/rfid_reader.py", line 44, in tagging
    raise CustomException("태깅 시간 초과", status_code=404)
rfid.exceptions.CustomException: 태깅 시간 초과

During handling of the above exception, another exception occurred:

Traceback (most recent call last):
  File "/usr/local/lib/python3.11/dist-packages/django/core/handlers/exception.py", line 55, in inner
    response = get_response(request)
               ^^^^^^^^^^^^^^^^^^^^^
  File "/usr/local/lib/python3.11/dist-packages/django/core/handlers/base.py", line 197, in _get_response
    response = wrapped_callback(request, *callback_args, **callback_kwargs)
               ^^^^^^^^^^^^^^^^^^^^^^^^^^^^^^^^^^^^^^^^^^^^^^^^^^^^^^^^^^^^
  File "/home/pi/rasp/rfid/views_v2.py", line 54, in disposal
    raise CustomException("태깅 중 오류 발생", status_code=500)
rfid.exceptions.CustomException: 태깅 중 오류 발생
ERROR 2024-11-26 05:05:34,558 basehttp "POST /disposal/ HTTP/1.1" 500 1860
ERROR 2024-11-26 05:05:34,581 log Internal Server Error: /favicon.ico
ERROR 2024-11-26 05:05:34,581 basehttp "GET /favicon.ico HTTP/1.1" 500 1860
ERROR 2024-11-26 05:05:38,185 log Internal Server Error: /favicon.ico
ERROR 2024-11-26 05:05:38,186 basehttp "GET /favicon.ico HTTP/1.1" 500 1860
ERROR 2024-11-26 05:05:48,951 log Internal Server Error: /disposal/
Traceback (most recent call last):
  File "/home/pi/rasp/rfid/views_v2.py", line 40, in disposal
    uid = rfid_reader.tagging()
          ^^^^^^^^^^^^^^^^^^^^^
  File "/home/pi/rasp/rfid/rfid_reader.py", line 44, in tagging
    raise CustomException("태깅 시간 초과", status_code=404)
rfid.exceptions.CustomException: 태깅 시간 초과

During handling of the above exception, another exception occurred:

Traceback (most recent call last):
  File "/usr/local/lib/python3.11/dist-packages/django/core/handlers/exception.py", line 55, in inner
    response = get_response(request)
               ^^^^^^^^^^^^^^^^^^^^^
  File "/usr/local/lib/python3.11/dist-packages/django/core/handlers/base.py", line 197, in _get_response
    response = wrapped_callback(request, *callback_args, **callback_kwargs)
               ^^^^^^^^^^^^^^^^^^^^^^^^^^^^^^^^^^^^^^^^^^^^^^^^^^^^^^^^^^^^
  File "/home/pi/rasp/rfid/views_v2.py", line 54, in disposal
    raise CustomException("태깅 중 오류 발생", status_code=500)
rfid.exceptions.CustomException: 태깅 중 오류 발생
ERROR 2024-11-26 05:05:48,954 basehttp "POST /disposal/ HTTP/1.1" 500 1860
ERROR 2024-11-26 05:05:48,975 log Internal Server Error: /favicon.ico
ERROR 2024-11-26 05:05:48,975 basehttp "GET /favicon.ico HTTP/1.1" 500 1860
ERROR 2024-11-26 05:05:53,138 log Internal Server Error: /favicon.ico
ERROR 2024-11-26 05:05:53,138 basehttp "GET /favicon.ico HTTP/1.1" 500 1860
ERROR 2024-11-26 05:06:03,785 log Internal Server Error: /disposal/
Traceback (most recent call last):
  File "/home/pi/rasp/rfid/views_v2.py", line 40, in disposal
    uid = rfid_reader.tagging()
          ^^^^^^^^^^^^^^^^^^^^^
  File "/home/pi/rasp/rfid/rfid_reader.py", line 44, in tagging
    raise CustomException("태깅 시간 초과", status_code=404)
rfid.exceptions.CustomException: 태깅 시간 초과

During handling of the above exception, another exception occurred:

Traceback (most recent call last):
  File "/usr/local/lib/python3.11/dist-packages/django/core/handlers/exception.py", line 55, in inner
    response = get_response(request)
               ^^^^^^^^^^^^^^^^^^^^^
  File "/usr/local/lib/python3.11/dist-packages/django/core/handlers/base.py", line 197, in _get_response
    response = wrapped_callback(request, *callback_args, **callback_kwargs)
               ^^^^^^^^^^^^^^^^^^^^^^^^^^^^^^^^^^^^^^^^^^^^^^^^^^^^^^^^^^^^
  File "/home/pi/rasp/rfid/views_v2.py", line 54, in disposal
    raise CustomException("태깅 중 오류 발생", status_code=500)
rfid.exceptions.CustomException: 태깅 중 오류 발생
ERROR 2024-11-26 05:06:03,786 basehttp "POST /disposal/ HTTP/1.1" 500 1860
ERROR 2024-11-26 05:06:03,811 log Internal Server Error: /favicon.ico
ERROR 2024-11-26 05:06:03,812 basehttp "GET /favicon.ico HTTP/1.1" 500 1860
ERROR 2024-11-26 05:06:48,334 log Internal Server Error: /favicon.ico
ERROR 2024-11-26 05:06:48,334 basehttp "GET /favicon.ico HTTP/1.1" 500 1860
ERROR 2024-11-26 05:06:59,025 log Internal Server Error: /disposal/
Traceback (most recent call last):
  File "/home/pi/rasp/rfid/views_v2.py", line 40, in disposal
    uid = rfid_reader.tagging()
          ^^^^^^^^^^^^^^^^^^^^^
  File "/home/pi/rasp/rfid/rfid_reader.py", line 44, in tagging
    raise CustomException("태깅 시간 초과", status_code=404)
rfid.exceptions.CustomException: 태깅 시간 초과

During handling of the above exception, another exception occurred:

Traceback (most recent call last):
  File "/usr/local/lib/python3.11/dist-packages/django/core/handlers/exception.py", line 55, in inner
    response = get_response(request)
               ^^^^^^^^^^^^^^^^^^^^^
  File "/usr/local/lib/python3.11/dist-packages/django/core/handlers/base.py", line 197, in _get_response
    response = wrapped_callback(request, *callback_args, **callback_kwargs)
               ^^^^^^^^^^^^^^^^^^^^^^^^^^^^^^^^^^^^^^^^^^^^^^^^^^^^^^^^^^^^
  File "/home/pi/rasp/rfid/views_v2.py", line 54, in disposal
    raise CustomException("태깅 중 오류 발생", status_code=500)
rfid.exceptions.CustomException: 태깅 중 오류 발생
ERROR 2024-11-26 05:06:59,026 basehttp "POST /disposal/ HTTP/1.1" 500 1860
ERROR 2024-11-26 05:06:59,052 log Internal Server Error: /favicon.ico
ERROR 2024-11-26 05:06:59,052 basehttp "GET /favicon.ico HTTP/1.1" 500 1860
ERROR 2024-11-26 05:07:11,223 log Internal Server Error: /favicon.ico
ERROR 2024-11-26 05:07:11,224 basehttp "GET /favicon.ico HTTP/1.1" 500 1860
ERROR 2024-11-26 05:07:22,968 log Internal Server Error: /disposal/
Traceback (most recent call last):
  File "/home/pi/rasp/rfid/views_v2.py", line 40, in disposal
    uid = rfid_reader.tagging()
          ^^^^^^^^^^^^^^^^^^^^^
  File "/home/pi/rasp/rfid/rfid_reader.py", line 44, in tagging
    raise CustomException("태깅 시간 초과", status_code=404)
rfid.exceptions.CustomException: 태깅 시간 초과

During handling of the above exception, another exception occurred:

Traceback (most recent call last):
  File "/usr/local/lib/python3.11/dist-packages/django/core/handlers/exception.py", line 55, in inner
    response = get_response(request)
               ^^^^^^^^^^^^^^^^^^^^^
  File "/usr/local/lib/python3.11/dist-packages/django/core/handlers/base.py", line 197, in _get_response
    response = wrapped_callback(request, *callback_args, **callback_kwargs)
               ^^^^^^^^^^^^^^^^^^^^^^^^^^^^^^^^^^^^^^^^^^^^^^^^^^^^^^^^^^^^
  File "/home/pi/rasp/rfid/views_v2.py", line 54, in disposal
    raise CustomException("태깅 중 오류 발생", status_code=500)
rfid.exceptions.CustomException: 태깅 중 오류 발생
ERROR 2024-11-26 05:07:22,969 basehttp "POST /disposal/ HTTP/1.1" 500 1860
ERROR 2024-11-26 05:07:22,991 log Internal Server Error: /favicon.ico
ERROR 2024-11-26 05:07:22,991 basehttp "GET /favicon.ico HTTP/1.1" 500 1860
ERROR 2024-11-26 05:07:40,821 log Internal Server Error: /favicon.ico
ERROR 2024-11-26 05:07:40,821 basehttp "GET /favicon.ico HTTP/1.1" 500 1860
ERROR 2024-11-26 05:08:47,824 log Internal Server Error: /disposal/
Traceback (most recent call last):
  File "/home/pi/rasp/rfid/views_v2.py", line 40, in disposal
    uid = rfid_reader.tagging()
          ^^^^^^^^^^^^^^^^^^^^^
  File "/home/pi/rasp/rfid/rfid_reader.py", line 44, in tagging
    raise CustomException("태깅 시간 초과", status_code=404)
rfid.exceptions.CustomException: 태깅 시간 초과

During handling of the above exception, another exception occurred:

Traceback (most recent call last):
  File "/usr/local/lib/python3.11/dist-packages/django/core/handlers/exception.py", line 55, in inner
    response = get_response(request)
               ^^^^^^^^^^^^^^^^^^^^^
  File "/usr/local/lib/python3.11/dist-packages/django/core/handlers/base.py", line 197, in _get_response
    response = wrapped_callback(request, *callback_args, **callback_kwargs)
               ^^^^^^^^^^^^^^^^^^^^^^^^^^^^^^^^^^^^^^^^^^^^^^^^^^^^^^^^^^^^
  File "/home/pi/rasp/rfid/views_v2.py", line 54, in disposal
    raise CustomException("태깅 중 오류 발생", status_code=500)
rfid.exceptions.CustomException: 태깅 중 오류 발생
ERROR 2024-11-26 05:08:47,825 basehttp "POST /disposal/ HTTP/1.1" 500 1860
ERROR 2024-11-26 05:08:47,845 log Internal Server Error: /favicon.ico
ERROR 2024-11-26 05:08:47,846 basehttp "GET /favicon.ico HTTP/1.1" 500 1860
ERROR 2024-11-26 05:09:20,320 log Internal Server Error: /favicon.ico
ERROR 2024-11-26 05:09:20,320 basehttp "GET /favicon.ico HTTP/1.1" 500 1860
ERROR 2024-11-26 05:16:28,387 log Internal Server Error: /favicon.ico
ERROR 2024-11-26 05:16:28,387 basehttp "GET /favicon.ico HTTP/1.1" 500 1860
ERROR 2024-11-26 05:16:29,405 log Internal Server Error: /disposal/
Traceback (most recent call last):
  File "/usr/local/lib/python3.11/dist-packages/django/core/handlers/exception.py", line 55, in inner
    response = get_response(request)
               ^^^^^^^^^^^^^^^^^^^^^
  File "/usr/local/lib/python3.11/dist-packages/django/core/handlers/base.py", line 204, in _get_response
    self.check_response(response, callback)
  File "/usr/local/lib/python3.11/dist-packages/django/core/handlers/base.py", line 332, in check_response
    raise ValueError(
ValueError: The view rfid.views_v2.disposal didn't return an HttpResponse object. It returned None instead.
ERROR 2024-11-26 05:16:29,407 basehttp "POST /disposal/ HTTP/1.1" 500 1860
ERROR 2024-11-26 05:16:29,428 log Internal Server Error: /favicon.ico
ERROR 2024-11-26 05:16:29,429 basehttp "GET /favicon.ico HTTP/1.1" 500 1860
ERROR 2024-11-26 05:16:30,294 log Internal Server Error: /favicon.ico
ERROR 2024-11-26 05:16:30,295 basehttp "GET /favicon.ico HTTP/1.1" 500 1860
ERROR 2024-11-26 05:16:31,156 log Internal Server Error: /disposal/
Traceback (most recent call last):
  File "/usr/local/lib/python3.11/dist-packages/django/core/handlers/exception.py", line 55, in inner
    response = get_response(request)
               ^^^^^^^^^^^^^^^^^^^^^
  File "/usr/local/lib/python3.11/dist-packages/django/core/handlers/base.py", line 204, in _get_response
    self.check_response(response, callback)
  File "/usr/local/lib/python3.11/dist-packages/django/core/handlers/base.py", line 332, in check_response
    raise ValueError(
ValueError: The view rfid.views_v2.disposal didn't return an HttpResponse object. It returned None instead.
ERROR 2024-11-26 05:16:31,157 basehttp "POST /disposal/ HTTP/1.1" 500 1860
ERROR 2024-11-26 05:16:31,178 log Internal Server Error: /favicon.ico
ERROR 2024-11-26 05:16:31,179 basehttp "GET /favicon.ico HTTP/1.1" 500 1860
ERROR 2024-11-26 05:16:31,931 log Internal Server Error: /favicon.ico
ERROR 2024-11-26 05:16:31,932 basehttp "GET /favicon.ico HTTP/1.1" 500 1860
ERROR 2024-11-26 05:16:53,052 log Internal Server Error: /disposal/
Traceback (most recent call last):
  File "/usr/local/lib/python3.11/dist-packages/django/core/handlers/exception.py", line 55, in inner
    response = get_response(request)
               ^^^^^^^^^^^^^^^^^^^^^
  File "/usr/local/lib/python3.11/dist-packages/django/core/handlers/base.py", line 204, in _get_response
    self.check_response(response, callback)
  File "/usr/local/lib/python3.11/dist-packages/django/core/handlers/base.py", line 332, in check_response
    raise ValueError(
ValueError: The view rfid.views_v2.disposal didn't return an HttpResponse object. It returned None instead.
ERROR 2024-11-26 05:16:53,053 basehttp "POST /disposal/ HTTP/1.1" 500 1860
ERROR 2024-11-26 05:16:53,076 log Internal Server Error: /favicon.ico
ERROR 2024-11-26 05:16:53,077 basehttp "GET /favicon.ico HTTP/1.1" 500 1860
ERROR 2024-11-26 05:16:55,315 log Internal Server Error: /favicon.ico
ERROR 2024-11-26 05:16:55,315 basehttp "GET /favicon.ico HTTP/1.1" 500 1860
ERROR 2024-11-26 05:17:06,416 log Internal Server Error: /disposal/
Traceback (most recent call last):
  File "/usr/local/lib/python3.11/dist-packages/django/core/handlers/exception.py", line 55, in inner
    response = get_response(request)
               ^^^^^^^^^^^^^^^^^^^^^
  File "/usr/local/lib/python3.11/dist-packages/django/core/handlers/base.py", line 197, in _get_response
    response = wrapped_callback(request, *callback_args, **callback_kwargs)
               ^^^^^^^^^^^^^^^^^^^^^^^^^^^^^^^^^^^^^^^^^^^^^^^^^^^^^^^^^^^^
  File "/home/pi/rasp/rfid/views_v2.py", line 50, in disposal
    raise e
  File "/home/pi/rasp/rfid/views_v2.py", line 41, in disposal
    uid = rfid_reader.tagging()
          ^^^^^^^^^^^^^^^^^^^^^
  File "/home/pi/rasp/rfid/rfid_reader.py", line 44, in tagging
    raise CustomException("태깅 시간 초과", status_code=404)
rfid.exceptions.CustomException: 태깅 시간 초과
ERROR 2024-11-26 05:17:06,417 basehttp "POST /disposal/ HTTP/1.1" 500 1860
ERROR 2024-11-26 05:17:06,683 log Internal Server Error: /favicon.ico
ERROR 2024-11-26 05:17:06,683 basehttp "GET /favicon.ico HTTP/1.1" 500 1860
ERROR 2024-11-26 05:17:08,614 log Internal Server Error: /favicon.ico
ERROR 2024-11-26 05:17:08,615 basehttp "GET /favicon.ico HTTP/1.1" 500 1860
ERROR 2024-11-26 05:17:11,939 log Internal Server Error: /disposal/
Traceback (most recent call last):
  File "/usr/local/lib/python3.11/dist-packages/django/core/handlers/exception.py", line 55, in inner
    response = get_response(request)
               ^^^^^^^^^^^^^^^^^^^^^
  File "/usr/local/lib/python3.11/dist-packages/django/core/handlers/base.py", line 204, in _get_response
    self.check_response(response, callback)
  File "/usr/local/lib/python3.11/dist-packages/django/core/handlers/base.py", line 332, in check_response
    raise ValueError(
ValueError: The view rfid.views_v2.disposal didn't return an HttpResponse object. It returned None instead.
ERROR 2024-11-26 05:17:11,940 basehttp "POST /disposal/ HTTP/1.1" 500 1860
ERROR 2024-11-26 05:17:11,964 log Internal Server Error: /favicon.ico
ERROR 2024-11-26 05:17:11,964 basehttp "GET /favicon.ico HTTP/1.1" 500 1860
ERROR 2024-11-26 05:17:13,965 log Internal Server Error: /favicon.ico
ERROR 2024-11-26 05:17:13,966 basehttp "GET /favicon.ico HTTP/1.1" 500 1860
ERROR 2024-11-26 05:19:35,033 log Internal Server Error: /favicon.ico
ERROR 2024-11-26 05:19:35,033 basehttp "GET /favicon.ico HTTP/1.1" 500 1860
ERROR 2024-11-26 05:19:37,281 log Internal Server Error: /favicon.ico
ERROR 2024-11-26 05:19:37,281 basehttp "GET /favicon.ico HTTP/1.1" 500 1860
ERROR 2024-11-26 05:19:38,042 log Internal Server Error: /favicon.ico
ERROR 2024-11-26 05:19:38,042 basehttp "GET /favicon.ico HTTP/1.1" 500 1860
ERROR 2024-11-26 05:21:47,685 log Internal Server Error: /favicon.ico
ERROR 2024-11-26 05:21:47,685 basehttp "GET /favicon.ico HTTP/1.1" 500 1860
ERROR 2024-11-26 05:21:50,499 log Internal Server Error: /result/
Traceback (most recent call last):
  File "/usr/local/lib/python3.11/dist-packages/django/core/handlers/exception.py", line 55, in inner
    response = get_response(request)
               ^^^^^^^^^^^^^^^^^^^^^
  File "/usr/local/lib/python3.11/dist-packages/django/core/handlers/base.py", line 197, in _get_response
    response = wrapped_callback(request, *callback_args, **callback_kwargs)
               ^^^^^^^^^^^^^^^^^^^^^^^^^^^^^^^^^^^^^^^^^^^^^^^^^^^^^^^^^^^^
  File "/home/pi/rasp/rfid/views_v2.py", line 86, in result
    raise e
  File "/home/pi/rasp/rfid/views_v2.py", line 75, in result
    raise CustomException("사용자 확인 실패", status_code=404)
rfid.exceptions.CustomException: 사용자 확인 실패
ERROR 2024-11-26 05:21:50,500 basehttp "GET /result/?uid=195883367363&name=%EC%9D%B4%EC%B0%BD%ED%99%98&company=HD%ED%98%84%EB%8C%80%EB%AF%B8%ED%8F%AC HTTP/1.1" 500 1860
ERROR 2024-11-26 05:21:50,523 log Internal Server Error: /favicon.ico
ERROR 2024-11-26 05:21:50,523 basehttp "GET /favicon.ico HTTP/1.1" 500 1860
ERROR 2024-11-26 05:21:51,413 log Internal Server Error: /favicon.ico
ERROR 2024-11-26 05:21:51,413 basehttp "GET /favicon.ico HTTP/1.1" 500 1860
ERROR 2024-11-26 05:27:34,765 log Internal Server Error: /disposal/
Traceback (most recent call last):
  File "/home/pi/rasp/rfid/views_v2.py", line 50, in disposal
    raise e
  File "/home/pi/rasp/rfid/views_v2.py", line 41, in disposal
    uid = rfid_reader.tagging()
          ^^^^^^^^^^^^^^^^^^^^^
  File "/home/pi/rasp/rfid/rfid_reader.py", line 44, in tagging
    raise CustomException("태깅 시간 초과", status_code=404)
rfid.exceptions.CustomException: 태깅 시간 초과

During handling of the above exception, another exception occurred:

Traceback (most recent call last):
  File "/usr/local/lib/python3.11/dist-packages/django/core/handlers/exception.py", line 55, in inner
    response = get_response(request)
               ^^^^^^^^^^^^^^^^^^^^^
  File "/usr/local/lib/python3.11/dist-packages/django/core/handlers/base.py", line 197, in _get_response
    response = wrapped_callback(request, *callback_args, **callback_kwargs)
               ^^^^^^^^^^^^^^^^^^^^^^^^^^^^^^^^^^^^^^^^^^^^^^^^^^^^^^^^^^^^
  File "/home/pi/rasp/rfid/views_v2.py", line 55, in disposal
    message = f"사용자 {user.name}이(가) 확인되었습니다."
                     ^^^^
UnboundLocalError: cannot access local variable 'user' where it is not associated with a value
ERROR 2024-11-26 05:27:34,767 basehttp "POST /disposal/ HTTP/1.1" 500 131
ERROR 2024-11-26 05:27:34,800 log Internal Server Error: /favicon.ico
ERROR 2024-11-26 05:27:34,800 basehttp "GET /favicon.ico HTTP/1.1" 500 131
ERROR 2024-11-26 05:27:45,503 log Internal Server Error: /favicon.ico
ERROR 2024-11-26 05:27:45,503 basehttp "GET /favicon.ico HTTP/1.1" 500 131
ERROR 2024-11-26 05:28:58,185 log Internal Server Error: /favicon.ico
ERROR 2024-11-26 05:28:58,185 basehttp "GET /favicon.ico HTTP/1.1" 500 131
ERROR 2024-11-26 05:29:09,224 log Internal Server Error: /disposal/
Traceback (most recent call last):
  File "/home/pi/rasp/rfid/views_v2.py", line 50, in disposal
    raise e
  File "/home/pi/rasp/rfid/views_v2.py", line 41, in disposal
    uid = rfid_reader.tagging()
          ^^^^^^^^^^^^^^^^^^^^^
  File "/home/pi/rasp/rfid/rfid_reader.py", line 44, in tagging
    raise CustomException("태깅 시간 초과", status_code=404)
rfid.exceptions.CustomException: 태깅 시간 초과

During handling of the above exception, another exception occurred:

Traceback (most recent call last):
  File "/usr/local/lib/python3.11/dist-packages/django/core/handlers/exception.py", line 55, in inner
    response = get_response(request)
               ^^^^^^^^^^^^^^^^^^^^^
  File "/usr/local/lib/python3.11/dist-packages/django/core/handlers/base.py", line 197, in _get_response
    response = wrapped_callback(request, *callback_args, **callback_kwargs)
               ^^^^^^^^^^^^^^^^^^^^^^^^^^^^^^^^^^^^^^^^^^^^^^^^^^^^^^^^^^^^
  File "/home/pi/rasp/rfid/views_v2.py", line 55, in disposal
    message = f"사용자 {user.name}이(가) 확인되었습니다."
                     ^^^^
UnboundLocalError: cannot access local variable 'user' where it is not associated with a value
ERROR 2024-11-26 05:29:09,225 basehttp "POST /disposal/ HTTP/1.1" 500 131
ERROR 2024-11-26 05:29:09,261 log Internal Server Error: /favicon.ico
ERROR 2024-11-26 05:29:09,261 basehttp "GET /favicon.ico HTTP/1.1" 500 131
ERROR 2024-11-26 05:29:13,246 log Internal Server Error: /favicon.ico
ERROR 2024-11-26 05:29:13,247 basehttp "GET /favicon.ico HTTP/1.1" 500 131
ERROR 2024-11-26 05:29:39,607 log Internal Server Error: /favicon.ico
ERROR 2024-11-26 05:29:39,608 basehttp "GET /favicon.ico HTTP/1.1" 500 131
ERROR 2024-11-26 05:29:51,099 log Internal Server Error: /disposal/
Traceback (most recent call last):
  File "/home/pi/rasp/rfid/views_v2.py", line 50, in disposal
    raise e
  File "/home/pi/rasp/rfid/views_v2.py", line 41, in disposal
    uid = rfid_reader.tagging()
          ^^^^^^^^^^^^^^^^^^^^^
  File "/home/pi/rasp/rfid/rfid_reader.py", line 44, in tagging
    raise CustomException("태깅 시간 초과", status_code=404)
rfid.exceptions.CustomException: 태깅 시간 초과

During handling of the above exception, another exception occurred:

Traceback (most recent call last):
  File "/usr/local/lib/python3.11/dist-packages/django/core/handlers/exception.py", line 55, in inner
    response = get_response(request)
               ^^^^^^^^^^^^^^^^^^^^^
  File "/usr/local/lib/python3.11/dist-packages/django/core/handlers/base.py", line 197, in _get_response
    response = wrapped_callback(request, *callback_args, **callback_kwargs)
               ^^^^^^^^^^^^^^^^^^^^^^^^^^^^^^^^^^^^^^^^^^^^^^^^^^^^^^^^^^^^
  File "/home/pi/rasp/rfid/views_v2.py", line 55, in disposal
    message = f"사용자 {user.name}이(가) 확인되었습니다."
                     ^^^^
UnboundLocalError: cannot access local variable 'user' where it is not associated with a value
ERROR 2024-11-26 05:29:51,100 basehttp "POST /disposal/ HTTP/1.1" 500 131
ERROR 2024-11-26 05:29:51,136 log Internal Server Error: /favicon.ico
ERROR 2024-11-26 05:29:51,136 basehttp "GET /favicon.ico HTTP/1.1" 500 131
ERROR 2024-11-26 05:30:20,044 log Internal Server Error: /favicon.ico
ERROR 2024-11-26 05:30:20,044 basehttp "GET /favicon.ico HTTP/1.1" 500 131
ERROR 2024-11-26 05:30:24,673 log Internal Server Error: /favicon.ico
ERROR 2024-11-26 05:30:24,673 basehttp "GET /favicon.ico HTTP/1.1" 500 131
ERROR 2024-11-26 05:33:12,143 log Internal Server Error: /result/
Traceback (most recent call last):
  File "/usr/local/lib/python3.11/dist-packages/django/core/handlers/exception.py", line 55, in inner
    response = get_response(request)
               ^^^^^^^^^^^^^^^^^^^^^
  File "/usr/local/lib/python3.11/dist-packages/django/core/handlers/base.py", line 197, in _get_response
    response = wrapped_callback(request, *callback_args, **callback_kwargs)
               ^^^^^^^^^^^^^^^^^^^^^^^^^^^^^^^^^^^^^^^^^^^^^^^^^^^^^^^^^^^^
  File "/home/pi/rasp/rfid/views_v2.py", line 86, in result
    raise e
  File "/home/pi/rasp/rfid/views_v2.py", line 75, in result
    raise CustomException("사용자 확인 실패", status_code=404)
rfid.exceptions.CustomException: 사용자 확인 실패
ERROR 2024-11-26 05:33:12,145 basehttp "GET /result/?uid=596393001371&name=%ED%85%8C%EC%8A%A4%ED%8A%B8%EC%9C%A0%EC%A0%80&company=HD%ED%98%84%EB%8C%80%EB%AF%B8%ED%8F%AC HTTP/1.1" 500 131
ERROR 2024-11-26 05:33:12,182 log Internal Server Error: /favicon.ico
ERROR 2024-11-26 05:33:12,183 basehttp "GET /favicon.ico HTTP/1.1" 500 131
ERROR 2024-11-26 05:33:18,963 log Internal Server Error: /favicon.ico
ERROR 2024-11-26 05:33:18,963 basehttp "GET /favicon.ico HTTP/1.1" 500 131
ERROR 2024-11-26 05:33:22,485 log Internal Server Error: /favicon.ico
ERROR 2024-11-26 05:33:22,485 basehttp "GET /favicon.ico HTTP/1.1" 500 131
ERROR 2024-11-26 05:33:23,516 log Internal Server Error: /favicon.ico
ERROR 2024-11-26 05:33:23,517 basehttp "GET /favicon.ico HTTP/1.1" 500 131
ERROR 2024-11-26 05:33:24,204 log Internal Server Error: /favicon.ico
ERROR 2024-11-26 05:33:24,205 basehttp "GET /favicon.ico HTTP/1.1" 500 131
ERROR 2024-11-26 05:42:04,703 log Internal Server Error: /disposal/
Traceback (most recent call last):
  File "/home/pi/rasp/rfid/views_v2.py", line 51, in disposal
    raise e
  File "/home/pi/rasp/rfid/views_v2.py", line 42, in disposal
    uid = rfid_reader.tagging()
          ^^^^^^^^^^^^^^^^^^^^^
  File "/home/pi/rasp/rfid/rfid_reader.py", line 44, in tagging
    raise CustomException("태깅 시간 초과", status_code=404)
rfid.exceptions.CustomException: 태깅 시간 초과

During handling of the above exception, another exception occurred:

Traceback (most recent call last):
  File "/usr/local/lib/python3.11/dist-packages/django/core/handlers/exception.py", line 55, in inner
    response = get_response(request)
               ^^^^^^^^^^^^^^^^^^^^^
  File "/usr/local/lib/python3.11/dist-packages/django/core/handlers/base.py", line 197, in _get_response
    response = wrapped_callback(request, *callback_args, **callback_kwargs)
               ^^^^^^^^^^^^^^^^^^^^^^^^^^^^^^^^^^^^^^^^^^^^^^^^^^^^^^^^^^^^
  File "/home/pi/rasp/rfid/views_v2.py", line 56, in disposal
    message = f"사용자 {user.name}이(가) 확인되었습니다."
                     ^^^^
UnboundLocalError: cannot access local variable 'user' where it is not associated with a value
ERROR 2024-11-26 05:42:04,705 basehttp "POST /disposal/ HTTP/1.1" 500 1860
ERROR 2024-11-26 05:42:04,729 log Internal Server Error: /favicon.ico
ERROR 2024-11-26 05:42:04,729 basehttp "GET /favicon.ico HTTP/1.1" 500 1860
ERROR 2024-11-26 05:42:06,412 log Internal Server Error: /favicon.ico
ERROR 2024-11-26 05:42:06,412 basehttp "GET /favicon.ico HTTP/1.1" 500 1860
ERROR 2024-11-26 05:42:13,112 log Internal Server Error: /favicon.ico
ERROR 2024-11-26 05:42:13,112 basehttp "GET /favicon.ico HTTP/1.1" 500 1860
ERROR 2024-11-26 05:42:17,031 log Internal Server Error: /result/
Traceback (most recent call last):
  File "/usr/local/lib/python3.11/dist-packages/django/core/handlers/exception.py", line 55, in inner
    response = get_response(request)
               ^^^^^^^^^^^^^^^^^^^^^
  File "/usr/local/lib/python3.11/dist-packages/django/core/handlers/base.py", line 197, in _get_response
    response = wrapped_callback(request, *callback_args, **callback_kwargs)
               ^^^^^^^^^^^^^^^^^^^^^^^^^^^^^^^^^^^^^^^^^^^^^^^^^^^^^^^^^^^^
  File "/home/pi/rasp/rfid/views_v2.py", line 87, in result
    raise e
  File "/home/pi/rasp/rfid/views_v2.py", line 76, in result
    raise CustomException("사용자 확인 실패", status_code=404)
rfid.exceptions.CustomException: 사용자 확인 실패
ERROR 2024-11-26 05:42:17,032 basehttp "GET /result/?uid=195883367363&name=%EC%9D%B4%EC%B0%BD%ED%99%98&company=HD%ED%98%84%EB%8C%80%EB%AF%B8%ED%8F%AC HTTP/1.1" 500 1860
ERROR 2024-11-26 05:42:17,054 log Internal Server Error: /favicon.ico
ERROR 2024-11-26 05:42:17,054 basehttp "GET /favicon.ico HTTP/1.1" 500 1860
ERROR 2024-11-26 05:42:19,012 log Internal Server Error: /favicon.ico
ERROR 2024-11-26 05:42:19,012 basehttp "GET /favicon.ico HTTP/1.1" 500 1860
ERROR 2024-11-26 05:46:10,371 log Internal Server Error: /disposal/
Traceback (most recent call last):
  File "/home/pi/rasp/rfid/views_v2.py", line 51, in disposal
    raise e
  File "/home/pi/rasp/rfid/views_v2.py", line 42, in disposal
    uid = rfid_reader.tagging()
          ^^^^^^^^^^^^^^^^^^^^^
  File "/home/pi/rasp/rfid/rfid_reader.py", line 44, in tagging
    raise CustomException("태깅 시간 초과", status_code=404)
rfid.exceptions.CustomException: 태깅 시간 초과

During handling of the above exception, another exception occurred:

Traceback (most recent call last):
  File "/usr/local/lib/python3.11/dist-packages/django/core/handlers/exception.py", line 55, in inner
    response = get_response(request)
               ^^^^^^^^^^^^^^^^^^^^^
  File "/usr/local/lib/python3.11/dist-packages/django/core/handlers/base.py", line 197, in _get_response
    response = wrapped_callback(request, *callback_args, **callback_kwargs)
               ^^^^^^^^^^^^^^^^^^^^^^^^^^^^^^^^^^^^^^^^^^^^^^^^^^^^^^^^^^^^
  File "/home/pi/rasp/rfid/views_v2.py", line 56, in disposal
    message = f"사용자 {user.name}이(가) 확인되었습니다."
                     ^^^^
UnboundLocalError: cannot access local variable 'user' where it is not associated with a value
ERROR 2024-11-26 05:46:10,373 basehttp "POST /disposal/ HTTP/1.1" 500 1860
ERROR 2024-11-26 05:46:10,399 log Internal Server Error: /favicon.ico
ERROR 2024-11-26 05:46:10,400 basehttp "GET /favicon.ico HTTP/1.1" 500 1860
ERROR 2024-11-26 05:46:11,330 log Internal Server Error: /favicon.ico
ERROR 2024-11-26 05:46:11,330 basehttp "GET /favicon.ico HTTP/1.1" 500 1860
ERROR 2024-11-26 05:49:02,143 log Internal Server Error: /disposal/
Traceback (most recent call last):
  File "/home/pi/rasp/rfid/views_v2.py", line 51, in disposal
    raise e
  File "/home/pi/rasp/rfid/views_v2.py", line 42, in disposal
    uid = rfid_reader.tagging()
          ^^^^^^^^^^^^^^^^^^^^^
  File "/home/pi/rasp/rfid/rfid_reader.py", line 44, in tagging
    raise CustomException("태깅 시간 초과", status_code=404)
rfid.exceptions.CustomException: 태깅 시간 초과

During handling of the above exception, another exception occurred:

Traceback (most recent call last):
  File "/usr/local/lib/python3.11/dist-packages/django/core/handlers/exception.py", line 55, in inner
    response = get_response(request)
               ^^^^^^^^^^^^^^^^^^^^^
  File "/usr/local/lib/python3.11/dist-packages/django/core/handlers/base.py", line 197, in _get_response
    response = wrapped_callback(request, *callback_args, **callback_kwargs)
               ^^^^^^^^^^^^^^^^^^^^^^^^^^^^^^^^^^^^^^^^^^^^^^^^^^^^^^^^^^^^
  File "/home/pi/rasp/rfid/views_v2.py", line 56, in disposal
    message = f"사용자 {user.name}이(가) 확인되었습니다."
                     ^^^^
UnboundLocalError: cannot access local variable 'user' where it is not associated with a value
ERROR 2024-11-26 05:49:02,145 basehttp "POST /disposal/ HTTP/1.1" 500 1860
ERROR 2024-11-26 05:49:02,435 log Internal Server Error: /favicon.ico
ERROR 2024-11-26 05:49:02,436 basehttp "GET /favicon.ico HTTP/1.1" 500 1860
ERROR 2024-11-26 05:49:03,677 log Internal Server Error: /favicon.ico
ERROR 2024-11-26 05:49:03,677 basehttp "GET /favicon.ico HTTP/1.1" 500 1860
ERROR 2024-11-26 07:45:04,253 exception Invalid HTTP_HOST header: '10.150.8.165:8000'. You may need to add '10.150.8.165' to ALLOWED_HOSTS.
Traceback (most recent call last):
  File "/usr/local/lib/python3.11/dist-packages/django/core/handlers/exception.py", line 55, in inner
    response = get_response(request)
               ^^^^^^^^^^^^^^^^^^^^^
  File "/usr/local/lib/python3.11/dist-packages/django/utils/deprecation.py", line 128, in __call__
    response = self.process_request(request)
               ^^^^^^^^^^^^^^^^^^^^^^^^^^^^^
  File "/usr/local/lib/python3.11/dist-packages/django/middleware/common.py", line 48, in process_request
    host = request.get_host()
           ^^^^^^^^^^^^^^^^^^
  File "/usr/local/lib/python3.11/dist-packages/django/http/request.py", line 151, in get_host
    raise DisallowedHost(msg)
django.core.exceptions.DisallowedHost: Invalid HTTP_HOST header: '10.150.8.165:8000'. You may need to add '10.150.8.165' to ALLOWED_HOSTS.
ERROR 2024-11-26 07:50:52,255 exception Invalid HTTP_HOST header: '10.150.8.165:8000'. You may need to add '10.150.8.165' to ALLOWED_HOSTS.
Traceback (most recent call last):
  File "/usr/local/lib/python3.11/dist-packages/django/core/handlers/exception.py", line 55, in inner
    response = get_response(request)
               ^^^^^^^^^^^^^^^^^^^^^
  File "/usr/local/lib/python3.11/dist-packages/django/utils/deprecation.py", line 128, in __call__
    response = self.process_request(request)
               ^^^^^^^^^^^^^^^^^^^^^^^^^^^^^
  File "/usr/local/lib/python3.11/dist-packages/django/middleware/common.py", line 48, in process_request
    host = request.get_host()
           ^^^^^^^^^^^^^^^^^^
  File "/usr/local/lib/python3.11/dist-packages/django/http/request.py", line 151, in get_host
    raise DisallowedHost(msg)
django.core.exceptions.DisallowedHost: Invalid HTTP_HOST header: '10.150.8.165:8000'. You may need to add '10.150.8.165' to ALLOWED_HOSTS.
ERROR 2024-11-26 07:50:56,326 exception Invalid HTTP_HOST header: '10.150.8.165:8000'. You may need to add '10.150.8.165' to ALLOWED_HOSTS.
Traceback (most recent call last):
  File "/usr/local/lib/python3.11/dist-packages/django/core/handlers/exception.py", line 55, in inner
    response = get_response(request)
               ^^^^^^^^^^^^^^^^^^^^^
  File "/usr/local/lib/python3.11/dist-packages/django/utils/deprecation.py", line 128, in __call__
    response = self.process_request(request)
               ^^^^^^^^^^^^^^^^^^^^^^^^^^^^^
  File "/usr/local/lib/python3.11/dist-packages/django/middleware/common.py", line 48, in process_request
    host = request.get_host()
           ^^^^^^^^^^^^^^^^^^
  File "/usr/local/lib/python3.11/dist-packages/django/http/request.py", line 151, in get_host
    raise DisallowedHost(msg)
django.core.exceptions.DisallowedHost: Invalid HTTP_HOST header: '10.150.8.165:8000'. You may need to add '10.150.8.165' to ALLOWED_HOSTS.
ERROR 2024-11-26 22:42:16,163 log Internal Server Error: /disposal/
Traceback (most recent call last):
  File "/home/pi/rasp/rfid/views_v2.py", line 34, in wrapper
    return func(request, *args, **kwargs)
           ^^^^^^^^^^^^^^^^^^^^^^^^^^^^^^
  File "/home/pi/rasp/rfid/views_v2.py", line 66, in disposal
    uid = rfid_reader.tagging()
          ^^^^^^^^^^^^^^^^^^^^^
  File "/home/pi/rasp/rfid/rfid_reader.py", line 44, in tagging
    raise CustomException("태깅 시간 초과", status_code=404)
rfid.exceptions.CustomException: 태깅 시간 초과

During handling of the above exception, another exception occurred:

Traceback (most recent call last):
  File "/usr/local/lib/python3.11/dist-packages/django/core/handlers/exception.py", line 55, in inner
    response = get_response(request)
               ^^^^^^^^^^^^^^^^^^^^^
  File "/usr/local/lib/python3.11/dist-packages/django/core/handlers/base.py", line 197, in _get_response
    response = wrapped_callback(request, *callback_args, **callback_kwargs)
               ^^^^^^^^^^^^^^^^^^^^^^^^^^^^^^^^^^^^^^^^^^^^^^^^^^^^^^^^^^^^
  File "/home/pi/rasp/rfid/views_v2.py", line 38, in wrapper
    return render(request, 'errors/error.html', {
           ^^^^^^^^^^^^^^^^^^^^^^^^^^^^^^^^^^^^^^
  File "/usr/local/lib/python3.11/dist-packages/django/shortcuts.py", line 25, in render
    content = loader.render_to_string(template_name, context, request, using=using)
              ^^^^^^^^^^^^^^^^^^^^^^^^^^^^^^^^^^^^^^^^^^^^^^^^^^^^^^^^^^^^^^^^^^^^^
  File "/usr/local/lib/python3.11/dist-packages/django/template/loader.py", line 61, in render_to_string
    template = get_template(template_name, using=using)
               ^^^^^^^^^^^^^^^^^^^^^^^^^^^^^^^^^^^^^^^^
  File "/usr/local/lib/python3.11/dist-packages/django/template/loader.py", line 19, in get_template
    raise TemplateDoesNotExist(template_name, chain=chain)
django.template.exceptions.TemplateDoesNotExist: errors/error.html
ERROR 2024-11-26 22:42:16,167 basehttp "POST /disposal/ HTTP/1.1" 500 145
ERROR 2024-11-26 22:56:45,105 log Internal Server Error: /result/
Traceback (most recent call last):
  File "/home/pi/rasp/rfid/views_v2.py", line 34, in wrapper
    return func(request, *args, **kwargs)
           ^^^^^^^^^^^^^^^^^^^^^^^^^^^^^^
  File "/home/pi/rasp/rfid/views_v2.py", line 91, in result
    raise CustomException("열림 시에 이용한 카드와 동일한 카드를 대주세요", status_code=777)
rfid.exceptions.CustomException: 열림 시에 이용한 카드와 동일한 카드를 대주세요

During handling of the above exception, another exception occurred:

Traceback (most recent call last):
  File "/usr/local/lib/python3.11/dist-packages/django/core/handlers/exception.py", line 55, in inner
    response = get_response(request)
               ^^^^^^^^^^^^^^^^^^^^^
  File "/usr/local/lib/python3.11/dist-packages/django/core/handlers/base.py", line 197, in _get_response
    response = wrapped_callback(request, *callback_args, **callback_kwargs)
               ^^^^^^^^^^^^^^^^^^^^^^^^^^^^^^^^^^^^^^^^^^^^^^^^^^^^^^^^^^^^
  File "/home/pi/rasp/rfid/views_v2.py", line 38, in wrapper
    return render(request, 'error.html', {
           ^^^^^^^^^^^^^^^^^^^^^^^^^^^^^^^
  File "/usr/local/lib/python3.11/dist-packages/django/shortcuts.py", line 26, in render
    return HttpResponse(content, content_type, status)
           ^^^^^^^^^^^^^^^^^^^^^^^^^^^^^^^^^^^^^^^^^^^
  File "/usr/local/lib/python3.11/dist-packages/django/http/response.py", line 374, in __init__
    super().__init__(*args, **kwargs)
  File "/usr/local/lib/python3.11/dist-packages/django/http/response.py", line 139, in __init__
    raise ValueError("HTTP status code must be an integer from 100 to 599.")
ValueError: HTTP status code must be an integer from 100 to 599.
ERROR 2024-11-26 22:56:45,150 basehttp "GET /result/?uid=195883367363&name=%EC%9D%B4%EC%B0%BD%ED%99%98&company=HD%ED%98%84%EB%8C%80%EB%AF%B8%ED%8F%AC HTTP/1.1" 500 145
ERROR 2024-11-26 22:57:21,883 log Unknown Status Code: /result/
ERROR 2024-11-26 22:57:21,884 basehttp "GET /result/?uid=195883367363&name=%EC%9D%B4%EC%B0%BD%ED%99%98&company=HD%ED%98%84%EB%8C%80%EB%AF%B8%ED%8F%AC HTTP/1.1" 555 1875
ERROR 2024-11-26 23:45:01,155 log Internal Server Error: /user_add/
Traceback (most recent call last):
  File "/usr/local/lib/python3.11/dist-packages/django/core/handlers/exception.py", line 55, in inner
    response = get_response(request)
               ^^^^^^^^^^^^^^^^^^^^^
  File "/usr/local/lib/python3.11/dist-packages/django/core/handlers/base.py", line 197, in _get_response
    response = wrapped_callback(request, *callback_args, **callback_kwargs)
               ^^^^^^^^^^^^^^^^^^^^^^^^^^^^^^^^^^^^^^^^^^^^^^^^^^^^^^^^^^^^
  File "/home/pi/rasp/rfid/user_management.py", line 39, in add_user
    raise CustomException("이미 등록된 사용자입니다.", status_code=409)
rfid.exceptions.CustomException: 이미 등록된 사용자입니다.
ERROR 2024-11-26 23:45:01,156 basehttp "POST /user_add/ HTTP/1.1" 500 145
ERROR 2024-11-27 00:01:31,882 log Internal Server Error: /disposal/
ERROR 2024-11-27 00:01:31,883 basehttp "POST /disposal/ HTTP/1.1" 500 1852
ERROR 2024-11-27 00:01:33,585 log Internal Server Error: /disposal/
ERROR 2024-11-27 00:01:33,585 basehttp "POST /disposal/ HTTP/1.1" 500 1852
ERROR 2024-11-27 00:01:53,933 log Internal Server Error: /disposal/
ERROR 2024-11-27 00:01:53,934 basehttp "POST /disposal/ HTTP/1.1" 500 1852
ERROR 2024-11-27 00:02:13,279 log Internal Server Error: /disposal/
ERROR 2024-11-27 00:02:13,279 basehttp "POST /disposal/ HTTP/1.1" 500 1852
ERROR 2024-11-27 00:02:55,441 log Internal Server Error: /disposal/
Traceback (most recent call last):
  File "/home/pi/rasp/rfid/views_v2.py", line 34, in wrapper
    return func(request, *args, **kwargs)
           ^^^^^^^^^^^^^^^^^^^^^^^^^^^^^^
  File "/home/pi/rasp/rfid/views_v2.py", line 65, in disposal
    uid = rfid_reader.tagging()
          ^^^^^^^^^^^^^^^^^^^^^
TypeError: handle_exception.<locals>.wrapper() missing 1 required positional argument: 'request'

During handling of the above exception, another exception occurred:

Traceback (most recent call last):
  File "/usr/local/lib/python3.11/dist-packages/django/core/handlers/exception.py", line 55, in inner
    response = get_response(request)
               ^^^^^^^^^^^^^^^^^^^^^
  File "/usr/local/lib/python3.11/dist-packages/django/core/handlers/base.py", line 197, in _get_response
    response = wrapped_callback(request, *callback_args, **callback_kwargs)
               ^^^^^^^^^^^^^^^^^^^^^^^^^^^^^^^^^^^^^^^^^^^^^^^^^^^^^^^^^^^^
  File "/home/pi/rasp/rfid/views_v2.py", line 45, in wrapper
    return render(request, 'errors/error.html', {
           ^^^^^^^^^^^^^^^^^^^^^^^^^^^^^^^^^^^^^^
  File "/usr/local/lib/python3.11/dist-packages/django/shortcuts.py", line 25, in render
    content = loader.render_to_string(template_name, context, request, using=using)
              ^^^^^^^^^^^^^^^^^^^^^^^^^^^^^^^^^^^^^^^^^^^^^^^^^^^^^^^^^^^^^^^^^^^^^
  File "/usr/local/lib/python3.11/dist-packages/django/template/loader.py", line 61, in render_to_string
    template = get_template(template_name, using=using)
               ^^^^^^^^^^^^^^^^^^^^^^^^^^^^^^^^^^^^^^^^
  File "/usr/local/lib/python3.11/dist-packages/django/template/loader.py", line 19, in get_template
    raise TemplateDoesNotExist(template_name, chain=chain)
django.template.exceptions.TemplateDoesNotExist: errors/error.html
ERROR 2024-11-27 00:02:55,442 basehttp "POST /disposal/ HTTP/1.1" 500 145
ERROR 2024-11-27 00:03:09,708 log Internal Server Error: /disposal/
ERROR 2024-11-27 00:03:09,708 basehttp "POST /disposal/ HTTP/1.1" 500 1852
ERROR 2024-11-27 02:02:57,452 log Internal Server Error: /disposal/
ERROR 2024-11-27 02:02:57,453 basehttp "POST /disposal/ HTTP/1.1" 500 1852
ERROR 2024-11-27 02:03:03,484 log Internal Server Error: /disposal/
ERROR 2024-11-27 02:03:03,485 basehttp "POST /disposal/ HTTP/1.1" 500 1852
ERROR 2024-11-27 02:03:08,589 log Internal Server Error: /disposal/
ERROR 2024-11-27 02:03:08,589 basehttp "POST /disposal/ HTTP/1.1" 500 1852
ERROR 2024-11-27 02:35:58,323 log Internal Server Error: /result/
ERROR 2024-11-27 02:35:58,366 basehttp "GET /result/?uid=596393001371&name=%ED%85%8C%EC%8A%A4%ED%8A%B8%EC%9C%A0%EC%A0%80&company=HD%ED%98%84%EB%8C%80%EB%AF%B8%ED%8F%AC HTTP/1.1" 500 1852
ERROR 2024-11-27 02:43:08,458 log Internal Server Error: /result/
Traceback (most recent call last):
  File "/home/pi/rasp/rfid/utils.py", line 14, in wrapper
    return func(request, *args, **kwargs)
           ^^^^^^^^^^^^^^^^^^^^^^^^^^^^^^
  File "/home/pi/rasp/rfid/views_v2.py", line 90, in result
    extra_data={'uid': uid, 'name': name, 'company': company, 'message': weight_info['message']}
                                                                         ~~~~~~~~~~~^^^^^^^^^^^
KeyError: 'message'

During handling of the above exception, another exception occurred:

Traceback (most recent call last):
  File "/usr/local/lib/python3.11/dist-packages/django/core/handlers/exception.py", line 55, in inner
    response = get_response(request)
               ^^^^^^^^^^^^^^^^^^^^^
  File "/usr/local/lib/python3.11/dist-packages/django/core/handlers/base.py", line 197, in _get_response
    response = wrapped_callback(request, *callback_args, **callback_kwargs)
               ^^^^^^^^^^^^^^^^^^^^^^^^^^^^^^^^^^^^^^^^^^^^^^^^^^^^^^^^^^^^
  File "/home/pi/rasp/rfid/utils.py", line 29, in wrapper
    logger.error(f"예기치 못한 오류: {e}", exc_info=True)
    ^^^^^^
NameError: name 'logger' is not defined
ERROR 2024-11-27 02:43:08,461 basehttp "GET /result/?uid=195883367363&name=%EC%9D%B4%EC%B0%BD%ED%99%98&company=HD%ED%98%84%EB%8C%80%EB%AF%B8%ED%8F%AC HTTP/1.1" 500 145
ERROR 2024-11-27 02:44:35,857 log Internal Server Error: /result/
ERROR 2024-11-27 02:44:35,857 basehttp "GET /result/?uid=596393001371&name=%ED%85%8C%EC%8A%A4%ED%8A%B8%EC%9C%A0%EC%A0%80&company=HD%ED%98%84%EB%8C%80%EB%AF%B8%ED%8F%AC HTTP/1.1" 500 1852
ERROR 2024-11-27 02:58:52,664 log Internal Server Error: /result/
ERROR 2024-11-27 02:58:52,664 basehttp "GET /result/?uid=596393001371&name=%ED%85%8C%EC%8A%A4%ED%8A%B8%EC%9C%A0%EC%A0%80&company=HD%ED%98%84%EB%8C%80%EB%AF%B8%ED%8F%AC HTTP/1.1" 500 1852
ERROR 2024-11-27 04:35:20,941 log Internal Server Error: /result/
ERROR 2024-11-27 04:35:20,942 basehttp "GET /result/?uid=None&name=&company= HTTP/1.1" 500 1852
ERROR 2024-11-27 05:57:47,515 log Internal Server Error: /result/
ERROR 2024-11-27 05:57:47,558 basehttp "GET /result/?uid=596393001371&name=%ED%85%8C%EC%8A%A4%ED%8A%B8%EC%9C%A0%EC%A0%80&company=HD%ED%98%84%EB%8C%80%EB%AF%B8%ED%8F%AC HTTP/1.1" 500 1852
ERROR 2024-11-27 05:57:56,696 log Internal Server Error: /disposal/
ERROR 2024-11-27 05:57:56,696 basehttp "POST /disposal/ HTTP/1.1" 500 1852
ERROR 2024-11-27 06:28:19,974 log Internal Server Error: /disposal/
ERROR 2024-11-27 06:28:20,039 basehttp "POST /disposal/ HTTP/1.1" 500 1852
ERROR 2024-11-27 06:28:22,073 log Internal Server Error: /disposal/
ERROR 2024-11-27 06:28:22,073 basehttp "POST /disposal/ HTTP/1.1" 500 1852
ERROR 2024-11-27 06:28:26,999 log Internal Server Error: /disposal/
ERROR 2024-11-27 06:28:27,000 basehttp "POST /disposal/ HTTP/1.1" 500 1852
ERROR 2024-11-27 06:28:35,597 log Internal Server Error: /result/
ERROR 2024-11-27 06:28:35,597 basehttp "GET /result/?uid=596393001371&name=%ED%85%8C%EC%8A%A4%ED%8A%B8%EC%9C%A0%EC%A0%80&company=HD%ED%98%84%EB%8C%80%EB%AF%B8%ED%8F%AC HTTP/1.1" 500 1852
ERROR 2024-11-27 06:28:39,664 log Internal Server Error: /result/
ERROR 2024-11-27 06:28:39,664 basehttp "GET /result/?uid=596393001371&name=%ED%85%8C%EC%8A%A4%ED%8A%B8%EC%9C%A0%EC%A0%80&company=HD%ED%98%84%EB%8C%80%EB%AF%B8%ED%8F%AC HTTP/1.1" 500 1852
ERROR 2024-11-27 06:29:06,581 log Internal Server Error: /result/
ERROR 2024-11-27 06:29:06,582 basehttp "GET /result/?uid=596393001371&name=%ED%85%8C%EC%8A%A4%ED%8A%B8%EC%9C%A0%EC%A0%80&company=HD%ED%98%84%EB%8C%80%EB%AF%B8%ED%8F%AC HTTP/1.1" 500 1852
ERROR 2024-11-27 06:29:32,724 log Internal Server Error: /result/
ERROR 2024-11-27 06:29:32,725 basehttp "GET /result/?uid=596393001371&name=%ED%85%8C%EC%8A%A4%ED%8A%B8%EC%9C%A0%EC%A0%80&company=HD%ED%98%84%EB%8C%80%EB%AF%B8%ED%8F%AC HTTP/1.1" 500 1852
ERROR 2024-11-27 06:34:57,815 log Internal Server Error: /result/
ERROR 2024-11-27 06:34:57,815 basehttp "GET /result/?uid=596393001371&name=%ED%85%8C%EC%8A%A4%ED%8A%B8%EC%9C%A0%EC%A0%80&company=HD%ED%98%84%EB%8C%80%EB%AF%B8%ED%8F%AC HTTP/1.1" 500 1852
ERROR 2024-11-27 06:38:27,466 log Internal Server Error: /result/
ERROR 2024-11-27 06:38:27,467 basehttp "GET /result/?uid=596393001371&name=%ED%85%8C%EC%8A%A4%ED%8A%B8%EC%9C%A0%EC%A0%80&company=HD%ED%98%84%EB%8C%80%EB%AF%B8%ED%8F%AC HTTP/1.1" 500 1865
ERROR 2024-11-27 06:38:38,734 log Internal Server Error: /result/
ERROR 2024-11-27 06:38:38,735 basehttp "GET /result/?uid=596393001371&name=%ED%85%8C%EC%8A%A4%ED%8A%B8%EC%9C%A0%EC%A0%80&company=HD%ED%98%84%EB%8C%80%EB%AF%B8%ED%8F%AC HTTP/1.1" 500 1865
ERROR 2024-11-27 06:40:38,023 log Internal Server Error: /result/
ERROR 2024-11-27 06:40:38,023 basehttp "GET /result/?uid=596393001371&name=%ED%85%8C%EC%8A%A4%ED%8A%B8%EC%9C%A0%EC%A0%80&company=HD%ED%98%84%EB%8C%80%EB%AF%B8%ED%8F%AC HTTP/1.1" 500 1865
ERROR 2024-11-27 07:41:31,302 log Internal Server Error: /result/
ERROR 2024-11-27 07:41:31,303 basehttp "GET /result/?uid=195883367363&name=%EC%9D%B4%EC%B0%BD%ED%99%98&company=HD%ED%98%84%EB%8C%80%EB%AF%B8%ED%8F%AC HTTP/1.1" 500 1852
ERROR 2024-11-15 04:50:21,296 log Internal Server Error: /disposal/
ERROR 2024-11-15 04:50:21,296 basehttp "POST /disposal/ HTTP/1.1" 500 1852
ERROR 2024-11-15 12:08:35,686 log Internal Server Error: /result/
ERROR 2024-11-15 12:08:35,687 basehttp "GET /result/?uid=195883367363&name=%EC%9D%B4%EC%B0%BD%ED%99%98&company=hd%ED%98%84%EB%8C%80%EB%AF%B8%ED%8F%AC HTTP/1.1" 500 1848
ERROR 2024-11-15 12:13:01,862 log Internal Server Error: /result/
ERROR 2024-11-15 12:13:01,862 basehttp "GET /result/?uid=195883367363&name=%EC%9D%B4%EC%B0%BD%ED%99%98&company=hd%ED%98%84%EB%8C%80%EB%AF%B8%ED%8F%AC HTTP/1.1" 500 1848
ERROR 2024-11-15 12:13:42,942 log Internal Server Error: /result/
ERROR 2024-11-15 12:13:42,942 basehttp "GET /result/?uid=195883367363&name=%EC%9D%B4%EC%B0%BD%ED%99%98&company=hd%ED%98%84%EB%8C%80%EB%AF%B8%ED%8F%AC HTTP/1.1" 500 1848
ERROR 2024-11-15 12:13:52,457 log Internal Server Error: /result/
ERROR 2024-11-15 12:13:52,457 basehttp "GET /result/?uid=195883367363&name=%EC%9D%B4%EC%B0%BD%ED%99%98&company=hd%ED%98%84%EB%8C%80%EB%AF%B8%ED%8F%AC HTTP/1.1" 500 1848
ERROR 2024-11-15 12:14:10,183 log Internal Server Error: /result/
ERROR 2024-11-15 12:14:10,183 basehttp "GET /result/?uid=195883367363&name=%EC%9D%B4%EC%B0%BD%ED%99%98&company=hd%ED%98%84%EB%8C%80%EB%AF%B8%ED%8F%AC HTTP/1.1" 500 1848
ERROR 2024-11-15 12:15:40,431 log Internal Server Error: /result/
ERROR 2024-11-15 12:15:40,431 basehttp "GET /result/?uid=195883367363&name=%EC%9D%B4%EC%B0%BD%ED%99%98&company=hd%ED%98%84%EB%8C%80%EB%AF%B8%ED%8F%AC HTTP/1.1" 500 1848
ERROR 2024-11-15 12:16:38,921 log Internal Server Error: /result/
ERROR 2024-11-15 12:16:38,921 basehttp "GET /result/?uid=195883367363&name=%EC%9D%B4%EC%B0%BD%ED%99%98&company=hd%ED%98%84%EB%8C%80%EB%AF%B8%ED%8F%AC HTTP/1.1" 500 1848
ERROR 2024-11-15 12:16:44,263 log Internal Server Error: /result/
ERROR 2024-11-15 12:16:44,263 basehttp "GET /result/?uid=195883367363&name=%EC%9D%B4%EC%B0%BD%ED%99%98&company=hd%ED%98%84%EB%8C%80%EB%AF%B8%ED%8F%AC HTTP/1.1" 500 1848
ERROR 2024-11-15 12:16:51,690 log Internal Server Error: /result/
ERROR 2024-11-15 12:16:51,690 basehttp "GET /result/?uid=195883367363&name=%EC%9D%B4%EC%B0%BD%ED%99%98&company=hd%ED%98%84%EB%8C%80%EB%AF%B8%ED%8F%AC HTTP/1.1" 500 1848
ERROR 2024-11-15 12:21:16,246 log Internal Server Error: /result/
ERROR 2024-11-15 12:21:16,246 basehttp "GET /result/?uid=195883367363&name=%EC%9D%B4%EC%B0%BD%ED%99%98&company=hd%ED%98%84%EB%8C%80%EB%AF%B8%ED%8F%AC HTTP/1.1" 500 1848
ERROR 2024-11-15 12:23:35,096 log Internal Server Error: /result/
ERROR 2024-11-15 12:23:35,096 basehttp "GET /result/?uid=195883367363&name=%EC%9D%B4%EC%B0%BD%ED%99%98&company=hd%ED%98%84%EB%8C%80%EB%AF%B8%ED%8F%AC HTTP/1.1" 500 1848
ERROR 2024-11-15 12:24:36,380 log Internal Server Error: /result/
ERROR 2024-11-15 12:24:36,381 basehttp "GET /result/?uid=195883367363&name=%EC%9D%B4%EC%B0%BD%ED%99%98&company=hd%ED%98%84%EB%8C%80%EB%AF%B8%ED%8F%AC HTTP/1.1" 500 1848
ERROR 2024-11-15 12:27:30,144 log Internal Server Error: /result/
ERROR 2024-11-15 12:27:30,144 basehttp "GET /result/?uid=195883367363&name=%EC%9D%B4%EC%B0%BD%ED%99%98&company=hd%ED%98%84%EB%8C%80%EB%AF%B8%ED%8F%AC HTTP/1.1" 500 1848
ERROR 2024-11-15 12:27:47,045 log Internal Server Error: /result/
ERROR 2024-11-15 12:27:47,045 basehttp "GET /result/?uid=195883367363&name=%EC%9D%B4%EC%B0%BD%ED%99%98&company=hd%ED%98%84%EB%8C%80%EB%AF%B8%ED%8F%AC HTTP/1.1" 500 1848
ERROR 2024-11-15 12:28:07,566 log Internal Server Error: /result/
ERROR 2024-11-15 12:28:07,566 basehttp "GET /result/?uid=195883367363&name=%EC%9D%B4%EC%B0%BD%ED%99%98&company=hd%ED%98%84%EB%8C%80%EB%AF%B8%ED%8F%AC HTTP/1.1" 500 1848
ERROR 2024-11-15 12:28:20,799 log Internal Server Error: /result/
ERROR 2024-11-15 12:28:20,800 basehttp "GET /result/?uid=195883367363&name=%EC%9D%B4%EC%B0%BD%ED%99%98&company=hd%ED%98%84%EB%8C%80%EB%AF%B8%ED%8F%AC HTTP/1.1" 500 1848
ERROR 2024-11-15 12:28:52,766 log Internal Server Error: /result/
ERROR 2024-11-15 12:28:52,767 basehttp "GET /result/?uid=195883367363&name=%EC%9D%B4%EC%B0%BD%ED%99%98&company=hd%ED%98%84%EB%8C%80%EB%AF%B8%ED%8F%AC HTTP/1.1" 500 1848
ERROR 2024-11-15 12:43:55,957 log Internal Server Error: /result/
ERROR 2024-11-15 12:43:55,958 basehttp "GET /result/?uid=195883367363&name=%EC%9D%B4%EC%B0%BD%ED%99%98&company=hd%ED%98%84%EB%8C%80%EB%AF%B8%ED%8F%AC HTTP/1.1" 500 1852
ERROR 2024-11-15 12:44:27,359 log Internal Server Error: /result/
ERROR 2024-11-15 12:44:27,360 basehttp "GET /result/?uid=195883367363&name=%EC%9D%B4%EC%B0%BD%ED%99%98&company=hd%ED%98%84%EB%8C%80%EB%AF%B8%ED%8F%AC HTTP/1.1" 500 1848
ERROR 2024-11-15 12:48:00,595 log Internal Server Error: /result/
ERROR 2024-11-15 12:48:00,596 basehttp "GET /result/?uid=195883367363&name=%EC%9D%B4%EC%B0%BD%ED%99%98&company=hd%ED%98%84%EB%8C%80%EB%AF%B8%ED%8F%AC HTTP/1.1" 500 1848
ERROR 2024-11-15 12:48:45,902 log Internal Server Error: /result/
ERROR 2024-11-15 12:48:45,903 basehttp "GET /result/?uid=195883367363&name=%EC%9D%B4%EC%B0%BD%ED%99%98&company=hd%ED%98%84%EB%8C%80%EB%AF%B8%ED%8F%AC HTTP/1.1" 500 1848
ERROR 2024-11-15 12:49:06,868 log Internal Server Error: /result/
ERROR 2024-11-15 12:49:06,868 basehttp "GET /result/?uid=195883367363&name=%EC%9D%B4%EC%B0%BD%ED%99%98&company=hd%ED%98%84%EB%8C%80%EB%AF%B8%ED%8F%AC HTTP/1.1" 500 1848
ERROR 2024-11-15 12:51:10,287 log Internal Server Error: /result/
ERROR 2024-11-15 12:51:10,288 basehttp "GET /result/?uid=195883367363&name=%EC%9D%B4%EC%B0%BD%ED%99%98&company=hd%ED%98%84%EB%8C%80%EB%AF%B8%ED%8F%AC HTTP/1.1" 500 1848
ERROR 2024-11-15 12:51:37,729 log Internal Server Error: /result/
ERROR 2024-11-15 12:51:37,730 basehttp "GET /result/?uid=195883367363&name=%EC%9D%B4%EC%B0%BD%ED%99%98&company=hd%ED%98%84%EB%8C%80%EB%AF%B8%ED%8F%AC HTTP/1.1" 500 1848
ERROR 2024-11-15 12:52:07,134 log Internal Server Error: /result/
ERROR 2024-11-15 12:52:07,134 basehttp "GET /result/?uid=195883367363&name=%EC%9D%B4%EC%B0%BD%ED%99%98&company=hd%ED%98%84%EB%8C%80%EB%AF%B8%ED%8F%AC HTTP/1.1" 500 1848
ERROR 2024-11-15 12:52:18,331 log Internal Server Error: /result/
ERROR 2024-11-15 12:52:18,332 basehttp "GET /result/?uid=195883367363&name=%EC%9D%B4%EC%B0%BD%ED%99%98&company=hd%ED%98%84%EB%8C%80%EB%AF%B8%ED%8F%AC HTTP/1.1" 500 1848
ERROR 2024-11-15 12:52:31,566 log Internal Server Error: /result/
ERROR 2024-11-15 12:52:31,567 basehttp "GET /result/?uid=195883367363&name=%EC%9D%B4%EC%B0%BD%ED%99%98&company=hd%ED%98%84%EB%8C%80%EB%AF%B8%ED%8F%AC HTTP/1.1" 500 1848
ERROR 2024-11-15 13:33:58,582 log Internal Server Error: /result/
ERROR 2024-11-15 13:33:58,582 basehttp "GET /result/?uid=195883367363&name=%EC%9D%B4%EC%B0%BD%ED%99%98&company=hd%ED%98%84%EB%8C%80%EB%AF%B8%ED%8F%AC HTTP/1.1" 500 1848
ERROR 2024-11-15 16:09:51,356 log Internal Server Error: /disposal/
ERROR 2024-11-15 16:09:51,359 basehttp "POST /disposal/ HTTP/1.1" 500 1852
ERROR 2024-11-15 16:09:57,382 log Internal Server Error: /disposal/
ERROR 2024-11-15 16:09:57,383 basehttp "POST /disposal/ HTTP/1.1" 500 1852
ERROR 2024-11-15 16:10:32,234 log Internal Server Error: /disposal/
ERROR 2024-11-15 16:10:32,234 basehttp "POST /disposal/ HTTP/1.1" 500 1852
ERROR 2024-11-15 16:18:05,614 log Internal Server Error: /user_add/
ERROR 2024-11-15 16:18:05,615 basehttp "POST /user_add/ HTTP/1.1" 500 1903
ERROR 2024-11-15 16:25:36,224 log Internal Server Error: /user_add/
ERROR 2024-11-15 16:25:36,225 basehttp "POST /user_add/ HTTP/1.1" 500 1903
ERROR 2024-12-04 09:06:31,006 rfid_reader tagging Timeout: UID not detected
ERROR 2024-12-04 09:06:44,072 rfid_reader tagging Timeout: UID not detected
ERROR 2024-12-04 09:07:14,091 rfid_reader tagging Timeout: UID not detected
ERROR 2024-12-05 08:05:44,054 rfid_reader tagging Timeout: UID not detected
ERROR 2024-12-05 08:06:16,091 rfid_reader tagging Timeout: UID not detected
ERROR 2024-12-05 08:06:48,395 rfid_reader tagging Timeout: UID not detected
ERROR 2024-12-05 08:07:05,907 rfid_reader tagging Timeout: UID not detected
ERROR 2024-12-05 08:12:35,300 rfid_reader tagging Timeout: UID not detected
ERROR 2024-12-05 08:21:26,808 views_v2 result 세션에 UID가 없습니다.
ERROR 2024-12-05 08:21:41,728 rfid_reader tagging Timeout: UID not detected
ERROR 2024-12-05 11:34:27,269 rfid_reader tagging Timeout: UID not detected
ERROR 2024-12-05 11:35:37,489 weight update_weight 서버 오류 발생: 유효한 데이터가 수신되지 않았습니다. (Status Code: 404)
ERROR 2024-12-05 11:36:12,476 weight update_weight 서버 오류 발생: 유효한 데이터가 수신되지 않았습니다. (Status Code: 404)
ERROR 2024-12-05 11:43:29,838 utils wrapper 예기치 못한 오류: 'HttpResponse' object has no attribute 'name'
Traceback (most recent call last):
  File "/home/pi/Desktop/rasp_v3/rfid/utils.py", line 16, in wrapper
    return func(request, *args, **kwargs)
           ^^^^^^^^^^^^^^^^^^^^^^^^^^^^^^
  File "/home/pi/Desktop/rasp_v3/rfid/views_v2.py", line 58, in disposal
    message = f"사용자 {user.name}이(가) 확인되었습니다."
                     ^^^^^^^^^
AttributeError: 'HttpResponse' object has no attribute 'name'
ERROR 2024-12-05 11:43:42,319 utils wrapper 예기치 못한 오류: 'HttpResponse' object has no attribute 'name'
Traceback (most recent call last):
  File "/home/pi/Desktop/rasp_v3/rfid/utils.py", line 16, in wrapper
    return func(request, *args, **kwargs)
           ^^^^^^^^^^^^^^^^^^^^^^^^^^^^^^
  File "/home/pi/Desktop/rasp_v3/rfid/views_v2.py", line 58, in disposal
    message = f"사용자 {user.name}이(가) 확인되었습니다."
                     ^^^^^^^^^
AttributeError: 'HttpResponse' object has no attribute 'name'
ERROR 2024-12-05 11:44:28,885 weight update_weight 서버 오류 발생: 유효한 데이터가 수신되지 않았습니다. (Status Code: 404)
ERROR 2024-12-05 11:45:21,128 utils wrapper 예기치 못한 오류: 'HttpResponse' object has no attribute 'name'
Traceback (most recent call last):
  File "/home/pi/Desktop/rasp_v3/rfid/utils.py", line 16, in wrapper
    return func(request, *args, **kwargs)
           ^^^^^^^^^^^^^^^^^^^^^^^^^^^^^^
  File "/home/pi/Desktop/rasp_v3/rfid/views_v2.py", line 58, in disposal
    message = f"사용자 {user.name}이(가) 확인되었습니다."
                     ^^^^^^^^^
AttributeError: 'HttpResponse' object has no attribute 'name'
ERROR 2024-12-05 13:04:41,949 weight update_weight 서버 오류 발생: 유효한 데이터가 수신되지 않았습니다. (Status Code: 404)
ERROR 2024-12-05 13:16:04,096 utils wrapper 예기치 못한 오류: 'HttpResponse' object has no attribute 'name'
Traceback (most recent call last):
  File "/home/pi/Desktop/rasp_v3/rfid/utils.py", line 16, in wrapper
    return func(request, *args, **kwargs)
           ^^^^^^^^^^^^^^^^^^^^^^^^^^^^^^
  File "/home/pi/Desktop/rasp_v3/rfid/views_v2.py", line 58, in disposal
    message = f"사용자 {user.name}이(가) 확인되었습니다."
                     ^^^^^^^^^
AttributeError: 'HttpResponse' object has no attribute 'name'
ERROR 2024-12-05 13:22:14,064 utils wrapper 예기치 못한 오류: User matching query does not exist.
Traceback (most recent call last):
  File "/home/pi/Desktop/rasp_v3/rfid/utils.py", line 16, in wrapper
    return func(request, *args, **kwargs)
           ^^^^^^^^^^^^^^^^^^^^^^^^^^^^^^
  File "/home/pi/Desktop/rasp_v3/rfid/user_management.py", line 25, in check_user
    user = User.objects.get(uid=uid)
           ^^^^^^^^^^^^^^^^^^^^^^^^^
  File "/usr/local/lib/python3.11/dist-packages/django/db/models/manager.py", line 87, in manager_method
    return getattr(self.get_queryset(), name)(*args, **kwargs)
           ^^^^^^^^^^^^^^^^^^^^^^^^^^^^^^^^^^^^^^^^^^^^^^^^^^^
  File "/usr/local/lib/python3.11/dist-packages/django/db/models/query.py", line 649, in get
    raise self.model.DoesNotExist(
rfid.models.User.DoesNotExist: User matching query does not exist.
ERROR 2024-12-05 13:22:14,072 utils wrapper 예기치 못한 오류: 'HttpResponse' object has no attribute 'name'
Traceback (most recent call last):
  File "/home/pi/Desktop/rasp_v3/rfid/utils.py", line 16, in wrapper
    return func(request, *args, **kwargs)
           ^^^^^^^^^^^^^^^^^^^^^^^^^^^^^^
  File "/home/pi/Desktop/rasp_v3/rfid/views_v2.py", line 61, in disposal
    message = f"사용자 {user.name}이(가) 확인되었습니다."
                     ^^^^^^^^^
AttributeError: 'HttpResponse' object has no attribute 'name'
ERROR 2024-12-05 13:22:29,483 weight update_weight 서버 오류 발생: 유효한 데이터가 수신되지 않았습니다. (Status Code: 404)
ERROR 2024-12-05 13:37:46,109 utils wrapper 예기치 못한 오류: User matching query does not exist.
Traceback (most recent call last):
  File "/home/pi/Desktop/rasp_v3/rfid/utils.py", line 16, in wrapper
    return func(request, *args, **kwargs)
           ^^^^^^^^^^^^^^^^^^^^^^^^^^^^^^
  File "/home/pi/Desktop/rasp_v3/rfid/user_management.py", line 25, in check_user
    user = User.objects.get(uid=uid)
           ^^^^^^^^^^^^^^^^^^^^^^^^^
  File "/usr/local/lib/python3.11/dist-packages/django/db/models/manager.py", line 87, in manager_method
    return getattr(self.get_queryset(), name)(*args, **kwargs)
           ^^^^^^^^^^^^^^^^^^^^^^^^^^^^^^^^^^^^^^^^^^^^^^^^^^^
  File "/usr/local/lib/python3.11/dist-packages/django/db/models/query.py", line 649, in get
    raise self.model.DoesNotExist(
rfid.models.User.DoesNotExist: User matching query does not exist.
ERROR 2024-12-05 13:37:46,113 utils wrapper 예기치 못한 오류: 'HttpResponse' object has no attribute 'name'
Traceback (most recent call last):
  File "/home/pi/Desktop/rasp_v3/rfid/utils.py", line 16, in wrapper
    return func(request, *args, **kwargs)
           ^^^^^^^^^^^^^^^^^^^^^^^^^^^^^^
  File "/home/pi/Desktop/rasp_v3/rfid/views_v2.py", line 61, in disposal
    message = f"사용자 {user.name}이(가) 확인되었습니다."
                     ^^^^^^^^^
AttributeError: 'HttpResponse' object has no attribute 'name'
ERROR 2024-12-05 13:38:31,828 weight update_weight 서버 오류 발생: 유효한 데이터가 수신되지 않았습니다. (Status Code: 404)
ERROR 2024-12-05 13:41:12,099 utils wrapper 예기치 못한 오류: 'HttpResponse' object has no attribute 'name'
Traceback (most recent call last):
  File "/home/pi/Desktop/rasp_v3/rfid/utils.py", line 16, in wrapper
    return func(request, *args, **kwargs)
           ^^^^^^^^^^^^^^^^^^^^^^^^^^^^^^
  File "/home/pi/Desktop/rasp_v3/rfid/views_v2.py", line 62, in disposal
    message = f"사용자 {user.name}이(가) 확인되었습니다."
                     ^^^^^^^^^
AttributeError: 'HttpResponse' object has no attribute 'name'
ERROR 2024-12-05 13:41:18,416 utils wrapper 예기치 못한 오류: 'HttpResponse' object has no attribute 'name'
Traceback (most recent call last):
  File "/home/pi/Desktop/rasp_v3/rfid/utils.py", line 16, in wrapper
    return func(request, *args, **kwargs)
           ^^^^^^^^^^^^^^^^^^^^^^^^^^^^^^
  File "/home/pi/Desktop/rasp_v3/rfid/views_v2.py", line 62, in disposal
    message = f"사용자 {user.name}이(가) 확인되었습니다."
                     ^^^^^^^^^
AttributeError: 'HttpResponse' object has no attribute 'name'
ERROR 2024-12-05 13:41:33,125 utils wrapper 예기치 못한 오류: 'HttpResponse' object has no attribute 'name'
Traceback (most recent call last):
  File "/home/pi/Desktop/rasp_v3/rfid/utils.py", line 16, in wrapper
    return func(request, *args, **kwargs)
           ^^^^^^^^^^^^^^^^^^^^^^^^^^^^^^
  File "/home/pi/Desktop/rasp_v3/rfid/views_v2.py", line 62, in disposal
    message = f"사용자 {user.name}이(가) 확인되었습니다."
                     ^^^^^^^^^
AttributeError: 'HttpResponse' object has no attribute 'name'
ERROR 2024-12-05 13:41:37,946 utils wrapper 예기치 못한 오류: 'HttpResponse' object has no attribute 'name'
Traceback (most recent call last):
  File "/home/pi/Desktop/rasp_v3/rfid/utils.py", line 16, in wrapper
    return func(request, *args, **kwargs)
           ^^^^^^^^^^^^^^^^^^^^^^^^^^^^^^
  File "/home/pi/Desktop/rasp_v3/rfid/views_v2.py", line 62, in disposal
    message = f"사용자 {user.name}이(가) 확인되었습니다."
                     ^^^^^^^^^
AttributeError: 'HttpResponse' object has no attribute 'name'
ERROR 2024-12-05 13:42:35,765 rfid_reader tagging Timeout: UID not detected
ERROR 2024-12-05 13:42:35,765 user_management add_user 사용자 추가 오류: 태깅 시간 초과 (Status Code: 404)
ERROR 2024-12-05 13:46:38,505 weight update_weight 서버 오류 발생: 유효한 데이터가 수신되지 않았습니다. (Status Code: 404)
ERROR 2024-12-05 13:48:48,636 utils wrapper 예기치 못한 오류: User matching query does not exist.
Traceback (most recent call last):
  File "/home/pi/Desktop/rasp_v3/rfid/utils.py", line 16, in wrapper
    return func(request, *args, **kwargs)
           ^^^^^^^^^^^^^^^^^^^^^^^^^^^^^^
  File "/home/pi/Desktop/rasp_v3/rfid/user_management.py", line 25, in check_user
    user = User.objects.get(uid=uid)
           ^^^^^^^^^^^^^^^^^^^^^^^^^
  File "/usr/local/lib/python3.11/dist-packages/django/db/models/manager.py", line 87, in manager_method
    return getattr(self.get_queryset(), name)(*args, **kwargs)
           ^^^^^^^^^^^^^^^^^^^^^^^^^^^^^^^^^^^^^^^^^^^^^^^^^^^
  File "/usr/local/lib/python3.11/dist-packages/django/db/models/query.py", line 649, in get
    raise self.model.DoesNotExist(
rfid.models.User.DoesNotExist: User matching query does not exist.
ERROR 2024-12-05 13:48:48,642 utils wrapper 예기치 못한 오류: 'HttpResponse' object has no attribute 'name'
Traceback (most recent call last):
  File "/home/pi/Desktop/rasp_v3/rfid/utils.py", line 16, in wrapper
    return func(request, *args, **kwargs)
           ^^^^^^^^^^^^^^^^^^^^^^^^^^^^^^
  File "/home/pi/Desktop/rasp_v3/rfid/views_v2.py", line 62, in disposal
    message = f"사용자 {user.name}이(가) 확인되었습니다."
                     ^^^^^^^^^
AttributeError: 'HttpResponse' object has no attribute 'name'
ERROR 2024-12-05 13:49:18,151 utils wrapper 예기치 못한 오류: User matching query does not exist.
Traceback (most recent call last):
  File "/home/pi/Desktop/rasp_v3/rfid/utils.py", line 16, in wrapper
    return func(request, *args, **kwargs)
           ^^^^^^^^^^^^^^^^^^^^^^^^^^^^^^
  File "/home/pi/Desktop/rasp_v3/rfid/user_management.py", line 25, in check_user
    user = User.objects.get(uid=uid)
           ^^^^^^^^^^^^^^^^^^^^^^^^^
  File "/usr/local/lib/python3.11/dist-packages/django/db/models/manager.py", line 87, in manager_method
    return getattr(self.get_queryset(), name)(*args, **kwargs)
           ^^^^^^^^^^^^^^^^^^^^^^^^^^^^^^^^^^^^^^^^^^^^^^^^^^^
  File "/usr/local/lib/python3.11/dist-packages/django/db/models/query.py", line 649, in get
    raise self.model.DoesNotExist(
rfid.models.User.DoesNotExist: User matching query does not exist.
ERROR 2024-12-05 13:49:18,160 utils wrapper 예기치 못한 오류: 'HttpResponse' object has no attribute 'name'
Traceback (most recent call last):
  File "/home/pi/Desktop/rasp_v3/rfid/utils.py", line 16, in wrapper
    return func(request, *args, **kwargs)
           ^^^^^^^^^^^^^^^^^^^^^^^^^^^^^^
  File "/home/pi/Desktop/rasp_v3/rfid/views_v2.py", line 62, in disposal
    message = f"사용자 {user.name}이(가) 확인되었습니다."
                     ^^^^^^^^^
AttributeError: 'HttpResponse' object has no attribute 'name'
ERROR 2024-12-05 13:50:50,784 utils wrapper 예기치 못한 오류: User matching query does not exist.
Traceback (most recent call last):
  File "/home/pi/Desktop/rasp_v3/rfid/utils.py", line 16, in wrapper
    return func(request, *args, **kwargs)
           ^^^^^^^^^^^^^^^^^^^^^^^^^^^^^^
  File "/home/pi/Desktop/rasp_v3/rfid/user_management.py", line 25, in check_user
    user = User.objects.get(uid=uid)
           ^^^^^^^^^^^^^^^^^^^^^^^^^
  File "/usr/local/lib/python3.11/dist-packages/django/db/models/manager.py", line 87, in manager_method
    return getattr(self.get_queryset(), name)(*args, **kwargs)
           ^^^^^^^^^^^^^^^^^^^^^^^^^^^^^^^^^^^^^^^^^^^^^^^^^^^
  File "/usr/local/lib/python3.11/dist-packages/django/db/models/query.py", line 649, in get
    raise self.model.DoesNotExist(
rfid.models.User.DoesNotExist: User matching query does not exist.
ERROR 2024-12-05 13:50:50,788 utils wrapper 예기치 못한 오류: 'HttpResponse' object has no attribute 'name'
Traceback (most recent call last):
  File "/home/pi/Desktop/rasp_v3/rfid/utils.py", line 16, in wrapper
    return func(request, *args, **kwargs)
           ^^^^^^^^^^^^^^^^^^^^^^^^^^^^^^
  File "/home/pi/Desktop/rasp_v3/rfid/views_v2.py", line 62, in disposal
    message = f"사용자 {user.name}이(가) 확인되었습니다."
                     ^^^^^^^^^
AttributeError: 'HttpResponse' object has no attribute 'name'
ERROR 2024-12-05 13:50:58,417 utils wrapper 예기치 못한 오류: User matching query does not exist.
Traceback (most recent call last):
  File "/home/pi/Desktop/rasp_v3/rfid/utils.py", line 16, in wrapper
    return func(request, *args, **kwargs)
           ^^^^^^^^^^^^^^^^^^^^^^^^^^^^^^
  File "/home/pi/Desktop/rasp_v3/rfid/user_management.py", line 25, in check_user
    user = User.objects.get(uid=uid)
           ^^^^^^^^^^^^^^^^^^^^^^^^^
  File "/usr/local/lib/python3.11/dist-packages/django/db/models/manager.py", line 87, in manager_method
    return getattr(self.get_queryset(), name)(*args, **kwargs)
           ^^^^^^^^^^^^^^^^^^^^^^^^^^^^^^^^^^^^^^^^^^^^^^^^^^^
  File "/usr/local/lib/python3.11/dist-packages/django/db/models/query.py", line 649, in get
    raise self.model.DoesNotExist(
rfid.models.User.DoesNotExist: User matching query does not exist.
ERROR 2024-12-05 13:50:58,418 utils wrapper 예기치 못한 오류: 'HttpResponse' object has no attribute 'name'
Traceback (most recent call last):
  File "/home/pi/Desktop/rasp_v3/rfid/utils.py", line 16, in wrapper
    return func(request, *args, **kwargs)
           ^^^^^^^^^^^^^^^^^^^^^^^^^^^^^^
  File "/home/pi/Desktop/rasp_v3/rfid/views_v2.py", line 62, in disposal
    message = f"사용자 {user.name}이(가) 확인되었습니다."
                     ^^^^^^^^^
AttributeError: 'HttpResponse' object has no attribute 'name'
ERROR 2024-12-05 13:51:18,999 utils wrapper 예기치 못한 오류: User matching query does not exist.
Traceback (most recent call last):
  File "/home/pi/Desktop/rasp_v3/rfid/utils.py", line 16, in wrapper
    return func(request, *args, **kwargs)
           ^^^^^^^^^^^^^^^^^^^^^^^^^^^^^^
  File "/home/pi/Desktop/rasp_v3/rfid/views_v2.py", line 57, in disposal
    user = user_management.check_user(uid_session)
           ^^^^^^^^^^^^^^^^^^^^^^^^^^^^^^^^^^^^^^^
  File "/home/pi/Desktop/rasp_v3/rfid/user_management.py", line 24, in check_user
    user = User.objects.get(uid=uid)
           ^^^^^^^^^^^^^^^^^^^^^^^^^
  File "/usr/local/lib/python3.11/dist-packages/django/db/models/manager.py", line 87, in manager_method
    return getattr(self.get_queryset(), name)(*args, **kwargs)
           ^^^^^^^^^^^^^^^^^^^^^^^^^^^^^^^^^^^^^^^^^^^^^^^^^^^
  File "/usr/local/lib/python3.11/dist-packages/django/db/models/query.py", line 649, in get
    raise self.model.DoesNotExist(
rfid.models.User.DoesNotExist: User matching query does not exist.
ERROR 2024-12-05 13:52:50,079 utils wrapper 예기치 못한 오류: User matching query does not exist.
Traceback (most recent call last):
  File "/home/pi/Desktop/rasp_v3/rfid/utils.py", line 16, in wrapper
    return func(request, *args, **kwargs)
           ^^^^^^^^^^^^^^^^^^^^^^^^^^^^^^
  File "/home/pi/Desktop/rasp_v3/rfid/views_v2.py", line 57, in disposal
    user = user_management.check_user(uid_session)
           ^^^^^^^^^^^^^^^^^^^^^^^^^^^^^^^^^^^^^^^
  File "/home/pi/Desktop/rasp_v3/rfid/user_management.py", line 24, in check_user
    user = User.objects.get(uid=uid)
           ^^^^^^^^^^^^^^^^^^^^^^^^^
  File "/usr/local/lib/python3.11/dist-packages/django/db/models/manager.py", line 87, in manager_method
    return getattr(self.get_queryset(), name)(*args, **kwargs)
           ^^^^^^^^^^^^^^^^^^^^^^^^^^^^^^^^^^^^^^^^^^^^^^^^^^^
  File "/usr/local/lib/python3.11/dist-packages/django/db/models/query.py", line 649, in get
    raise self.model.DoesNotExist(
rfid.models.User.DoesNotExist: User matching query does not exist.
ERROR 2024-12-05 13:53:09,108 weight update_weight 서버 오류 발생: 유효한 데이터가 수신되지 않았습니다. (Status Code: 404)
ERROR 2024-12-05 14:02:06,639 utils wrapper 예기치 못한 오류: User matching query does not exist.
Traceback (most recent call last):
  File "/home/pi/Desktop/rasp_v3/rfid/utils.py", line 16, in wrapper
    return func(request, *args, **kwargs)
           ^^^^^^^^^^^^^^^^^^^^^^^^^^^^^^
  File "/home/pi/Desktop/rasp_v3/rfid/views_v2.py", line 57, in disposal
    user = user_management.check_user(uid_session)
           ^^^^^^^^^^^^^^^^^^^^^^^^^^^^^^^^^^^^^^^
  File "/home/pi/Desktop/rasp_v3/rfid/user_management.py", line 24, in check_user
    user = User.objects.get(uid=uid)
           ^^^^^^^^^^^^^^^^^^^^^^^^^
  File "/usr/local/lib/python3.11/dist-packages/django/db/models/manager.py", line 87, in manager_method
    return getattr(self.get_queryset(), name)(*args, **kwargs)
           ^^^^^^^^^^^^^^^^^^^^^^^^^^^^^^^^^^^^^^^^^^^^^^^^^^^
  File "/usr/local/lib/python3.11/dist-packages/django/db/models/query.py", line 649, in get
    raise self.model.DoesNotExist(
rfid.models.User.DoesNotExist: User matching query does not exist.
ERROR 2024-12-05 14:03:28,385 utils wrapper 예기치 못한 오류: 'Manager' object has no attribute 'get_object_or_404'
Traceback (most recent call last):
  File "/home/pi/Desktop/rasp_v3/rfid/utils.py", line 16, in wrapper
    return func(request, *args, **kwargs)
           ^^^^^^^^^^^^^^^^^^^^^^^^^^^^^^
  File "/home/pi/Desktop/rasp_v3/rfid/views_v2.py", line 57, in disposal
    user = user_management.check_user(uid_session)
           ^^^^^^^^^^^^^^^^^^^^^^^^^^^^^^^^^^^^^^^
  File "/home/pi/Desktop/rasp_v3/rfid/user_management.py", line 24, in check_user
    user = User.objects.get_object_or_404(uid=uid)
           ^^^^^^^^^^^^^^^^^^^^^^^^^^^^^^
AttributeError: 'Manager' object has no attribute 'get_object_or_404'
ERROR 2024-12-05 14:05:27,571 user_management check_user 사용자를 찾을 수 없음: UID 04 E3 43 6A 76 13 90
ERROR 2024-12-05 14:07:58,611 user_management check_user 사용자를 찾을 수 없음: UID 04 E3 43 6A 76 13 90
ERROR 2024-12-05 14:08:36,531 user_management check_user 사용자를 찾을 수 없음: UID 04 E3 43 6A 76 13 90
ERROR 2024-12-05 14:08:37,784 user_management check_user 사용자를 찾을 수 없음: UID 04 E3 43 6A 76 13 90
ERROR 2024-12-05 14:12:18,576 user_management check_user 사용자를 찾을 수 없음: UID 04 E3 43 6A 76 13 90
ERROR 2024-12-05 14:12:32,814 weight update_weight 서버 오류 발생: 유효한 데이터가 수신되지 않았습니다. (Status Code: 404)
ERROR 2024-12-05 14:12:47,017 user_management check_user 사용자를 찾을 수 없음: UID 04 E3 43 6A 76 13 90
ERROR 2024-12-05 14:13:47,263 user_management check_user 사용자를 찾을 수 없음: UID 04 E3 43 6A 76 13 90
